tests/32_threads/sample_98.in
32
o
16 S 101 4 1906 483
4 B 102 4 1850 161
2 S 104 8 1797 888
6 B 105 2 1046 329
21 S 107 2 1895 244
14 B 108 6 1658 653
28 B 109 1 1711 124
17 S 111 9 1712 31
28 C 109
17 S 113 0 1318 395
29 S 114 8 1995 124
16 B 115 5 1177 600
12 S 117 5 1751 521
31 S 118 8 1001 353
14 C 108
20 S 120 9 1197 998
23 S 121 1 1256 993
14 C 108
31 S 123 8 1413 459
9 S 124 6 1881 707
1 S 126 6 1470 473
30 S 127 1 1570 928
30 S 128 6 1427 654
3 S 130 5 1943 743
30 S 131 7 1158 720
9 S 132 2 1437 403
22 S 134 8 1549 303
19 S 135 5 1514 268
26 S 136 5 1839 739
6 C 105
30 C 127
19 S 139 3 1112 16
14 C 108
26 S 141 6 1969 277
6 S 142 8 1944 638
17 C 113
26 S 145 3 1993 591
9 S 147 9 1743 123
16 C 101
29 S 151 9 1456 868
0 S 152 0 1404 410
25 B 153 9 1079 741
11 B 154 5 1595 862
17 S 156 7 1439 816
28 S 157 9 1845 968
5 S 158 0 1096 655
19 C 139
23 C 121
13 S 161 6 1708 692
2 B 162 7 1119 472
10 B 163 3 1825 836
13 B 164 1 1526 466
19 C 135
10 B 166 2 1055 416
28 S 167 0 1813 892
14 C 108
19 S 169 7 1859 955
23 C 121
3 S 172 9 1929 81
16 B 173 8 1305 508
17 B 174 6 1752 827
15 S 175 1 1726 15
6 B 176 9 1509 762
20 C 120
9 S 178 5 1609 35
12 B 179 1 1375 311
19 C 139
13 B 181 4 1413 664
28 C 167
31 B 183 9 1348 582
10 C 163
9 C 132
15 S 186 8 1449 792
12 C 179
20 C 120
21 B 189 1 1877 312
13 B 190 7 1471 482
7 S 191 7 1866 979
4 B 192 6 1082 328
0 C 152
11 C 154
29 S 195 3 1037 133
21 B 196 1 1056 543
13 B 197 0 1461 559
13 C 190
25 C 153
29 B 200 9 1425 929
21 S 201 5 1731 208
15 C 175
6 C 105
23 S 204 5 1659 211
9 B 205 8 1944 948
19 S 206 2 1554 310
15 B 207 1 1495 767
11 B 208 9 1832 947
13 B 209 7 1506 297
14 B 210 2 1778 261
16 S 211 4 1487 793
14 C 108
19 C 206
14 B 214 7 1771 807
2 S 215 2 1213 574
13 B 216 7 1175 705
0 C 152
24 B 218 5 1224 796
20 C 120
28 C 109
6 S 221 7 1917 227
21 B 222 5 1850 811
15 B 224 5 1161 20
24 C 218
3 C 172
10 C 163
12 B 229 9 1624 358
7 B 230 0 1621 824
27 S 231 8 1981 890
22 B 232 0 1701 121
7 S 233 7 1697 659
5 C 158
5 B 235 0 1522 20
5 C 235
23 S 237 7 1306 207
8 S 238 8 1457 512
1 C 126
21 S 240 0 1056 846
14 B 241 7 1997 217
15 B 242 5 1472 590
30 S 243 9 1807 23
5 S 244 5 1635 343
31 C 118
27 C 231
11 C 154
7 B 248 0 1086 696
31 S 249 7 1502 565
30 B 250 1 1693 159
8 B 251 6 1546 451
7 B 252 5 1048 205
30 C 128
27 S 254 0 1088 238
23 S 255 4 1277 546
3 S 256 3 1757 596
12 B 257 0 1447 83
23 B 258 0 1453 208
1 S 259 2 1301 999
27 B 260 6 1047 278
18 S 261 3 1094 610
21 C 189
31 S 263 7 1625 252
25 B 264 5 1178 372
6 S 265 2 1757 614
18 S 266 3 1932 461
27 B 267 7 1719 608
7 B 268 0 1604 468
23 C 237
15 C 186
10 C 166
2 C 104
23 B 273 3 1570 317
29 S 274 5 1959 203
25 B 275 9 1876 602
19 C 135
27 B 277 8 1806 297
14 S 278 6 1642 734
30 C 250
9 C 132
15 S 281 3 1242 468
21 S 282 1 1329 453
30 C 250
25 C 275
6 B 285 1 1998 59
13 B 286 2 1261 587
4 S 287 4 1731 87
0 C 152
24 S 289 6 1026 280
27 C 254
3 C 256
17 S 292 3 1554 23
28 B 293 9 1727 571
16 B 294 3 1117 844
24 C 218
11 S 296 0 1152 362
15 B 297 3 1786 242
29 S 298 5 1353 402
31 S 299 7 1232 88
29 C 274
28 S 301 3 1871 167
29 C 200
10 C 166
30 B 304 9 1303 518
8 S 305 9 1011 190
22 C 232
24 B 307 7 1132 269
14 B 308 9 1363 185
17 S 309 3 1372 762
15 S 310 4 1434 992
18 C 261
17 S 312 6 1845 705
24 B 313 7 1421 361
10 B 314 3 1533 683
4 S 315 8 1664 957
23 C 121
11 S 317 2 1826 898
8 C 305
9 B 319 8 1082 350
24 B 320 5 1986 946
22 C 134
19 C 139
28 C 293
18 C 266
10 B 325 2 1343 185
2 S 326 2 1880 771
11 C 208
20 B 328 0 2000 199
11 C 317
2 B 330 6 1795 375
22 S 331 5 1513 255
3 B 332 8 1700 256
2 B 333 2 1228 193
27 C 260
22 S 335 2 1357 873
18 C 261
16 B 337 7 1851 172
27 C 254
13 S 339 3 1586 453
20 S 340 5 1806 488
28 C 109
5 B 342 5 1223 141
28 S 343 0 1488 463
8 B 344 7 1735 527
20 S 345 1 1234 869
1 S 346 7 1572 243
21 C 282
8 S 348 2 1138 165
1 B 349 1 1808 704
29 C 200
29 S 351 5 1883 924
7 B 352 2 1268 41
13 B 353 9 1417 286
5 C 158
25 S 355 0 1697 897
5 B 356 5 1507 649
23 C 121
21 B 358 9 1470 60
26 C 136
24 C 313
3 B 361 4 1361 25
4 B 362 2 1100 586
24 B 363 1 1805 686
4 B 364 3 1968 26
18 S 365 2 1777 770
29 S 366 8 1439 809
12 S 367 8 1753 800
11 C 154
26 C 145
1 B 370 2 1827 781
17 C 174
13 C 209
25 B 373 9 1388 301
6 B 374 9 1334 560
14 B 375 2 1518 644
16 S 376 0 1890 500
13 S 377 3 1816 964
9 B 378 1 1073 717
31 C 123
25 S 380 7 1919 223
29 S 381 4 1734 300
3 C 130
11 B 383 4 1739 183
9 B 384 4 1974 644
31 B 385 2 1020 690
22 B 386 1 1610 385
27 B 387 0 1286 801
19 C 206
5 B 389 1 1346 597
26 B 390 3 1453 859
6 B 391 8 1806 519
1 S 392 3 1601 390
8 S 393 9 1505 891
6 B 394 8 1212 164
17 B 395 8 1284 633
14 S 396 8 1611 764
24 B 397 6 1947 96
14 C 210
24 B 399 0 1684 364
28 C 109
7 C 191
21 S 402 0 1695 893
24 S 403 5 1627 739
3 C 172
31 B 405 1 1307 879
18 B 406 4 1961 64
3 C 130
6 S 408 7 1413 195
12 C 117
6 C 408
7 S 411 8 1231 982
31 S 412 1 1708 995
11 S 413 2 1015 61
24 B 414 0 1514 169
25 B 415 5 1943 136
5 C 158
23 C 237
23 C 204
20 B 419 1 1573 138
22 C 232
15 S 421 6 1534 635
21 C 402
5 S 423 8 1330 907
26 B 424 4 1529 677
12 C 367
20 C 340
12 S 427 5 1960 815
14 B 428 4 1424 418
4 C 192
29 B 430 9 1965 58
18 S 431 2 1011 481
5 S 432 5 1552 483
3 S 433 3 1209 501
18 B 434 9 1162 309
31 S 435 6 1048 638
16 C 211
31 B 437 5 1297 198
22 C 386
25 S 439 0 1239 274
8 B 440 7 1008 112
5 B 441 5 1101 513
21 B 442 0 1997 918
12 C 229
4 C 287
28 C 157
0 S 446 8 1332 31
30 B 447 9 1921 138
16 S 448 9 1310 153
19 B 449 4 1823 155
1 C 259
17 C 174
17 B 452 9 1835 479
11 S 453 9 1970 577
31 S 454 2 1484 626
12 B 455 4 1661 646
11 C 208
14 C 308
23 S 458 9 1828 949
16 S 459 6 1541 569
24 S 460 5 1992 55
17 B 461 9 1653 207
29 B 462 8 1785 282
5 C 432
26 B 464 1 1483 454
20 C 340
28 B 466 9 1807 222
15 B 467 6 1705 942
16 C 337
31 S 469 0 1321 231
25 B 470 3 1073 111
15 S 471 3 1766 992
15 B 472 1 1549 316
4 S 473 0 1776 661
19 B 474 3 1541 696
10 S 475 0 1357 358
16 C 294
11 S 477 4 1369 666
3 C 433
31 B 479 6 1469 530
18 S 480 6 1504 666
2 C 162
9 B 482 0 1462 131
30 B 483 4 1447 347
5 C 244
26 S 485 9 1670 398
26 S 486 0 1475 97
10 C 475
0 C 152
28 C 343
25 S 490 4 1941 464
2 C 333
6 S 492 3 1643 777
3 B 493 9 1000 677
3 C 332
21 B 495 0 1416 659
7 C 268
5 C 389
14 S 498 9 1571 237
29 S 499 2 1839 886
11 C 413
13 S 501 6 1071 661
24 S 502 2 1546 771
21 B 503 2 1423 699
23 C 258
7 S 505 1 1238 598
24 B 506 9 1361 848
29 B 507 2 1717 38
10 S 508 1 1714 914
21 C 503
1 B 510 8 1989 319
30 S 511 1 1149 218
11 S 512 4 1018 717
7 S 513 1 1084 914
8 C 393
1 C 510
27 C 260
1 S 517 8 1971 630
23 S 518 6 1277 282
2 C 326
6 S 520 6 1986 477
9 C 147
30 S 522 6 1479 949
11 C 383
22 B 524 3 1473 224
14 C 498
2 C 162
25 B 527 2 1310 510
17 C 174
6 C 105
6 B 530 0 1589 299
17 C 156
4 S 532 7 1972 347
30 B 533 3 1353 243
20 C 328
9 B 535 8 1342 273
12 B 536 2 1123 588
28 C 167
22 S 538 1 1902 937
19 S 539 9 1101 174
23 S 540 8 1208 627
17 S 541 6 1111 595
15 B 542 4 1890 149
10 C 475
12 B 544 0 1272 518
31 C 435
6 B 546 2 1720 429
24 B 547 4 1578 50
29 S 548 7 1333 104
27 B 549 4 1838 949
4 S 550 1 1909 788
15 B 551 5 1624 316
10 B 552 2 1830 112
6 B 553 0 1813 515
7 S 554 0 1713 39
25 B 555 8 1027 864
1 S 556 3 1331 351
27 C 387
11 B 558 3 1853 140
10 B 559 3 1344 881
23 B 560 3 1197 72
23 B 561 3 1701 187
14 C 375
10 B 563 4 1039 633
26 C 424
26 C 136
17 S 566 2 1775 346
8 S 567 5 1237 832
18 C 406
7 S 569 9 1888 393
29 S 570 7 1468 779
29 C 507
21 S 572 0 1973 827
18 C 261
17 B 574 3 1021 447
9 C 147
7 C 513
13 C 216
25 C 555
9 B 579 6 1329 305
3 C 433
27 C 231
7 S 582 7 1181 26
9 B 583 4 1759 827
22 S 584 1 1829 948
1 S 585 0 1952 469
19 C 449
17 C 309
3 C 256
1 C 517
25 B 590 1 1808 944
20 B 591 1 1202 327
11 B 592 7 1768 973
16 C 294
19 B 594 1 1274 405
7 S 595 2 1079 393
15 C 242
18 S 597 7 1729 290
28 B 598 4 1798 167
30 B 599 4 1103 767
2 S 600 0 1274 909
3 B 601 6 1327 504
18 B 602 1 1572 144
12 S 603 1 1254 107
1 B 604 7 1295 202
22 B 605 6 1317 411
7 C 411
10 C 559
10 B 608 2 1411 83
16 B 609 9 1157 28
23 C 121
1 S 611 3 1529 563
12 C 367
17 S 613 7 1769 951
22 B 614 1 1500 204
