tests/32_threads/sample_99.in
32
o
13 S 103 5 1618 538
30 S 104 9 1010 497
16 B 105 4 1921 397
27 B 108 9 1379 713
4 S 110 9 1468 368
22 S 111 4 1073 138
6 B 114 0 1057 208
21 S 115 9 1945 667
20 S 116 8 1628 835
29 S 117 2 1627 809
9 B 118 5 1467 153
20 B 120 2 1378 15
25 B 123 6 1232 842
20 S 124 8 1655 857
7 S 125 8 1179 340
20 S 127 4 1642 942
12 B 129 3 1894 418
4 S 130 9 1436 958
19 S 131 9 1490 617
4 C 130
16 S 134 9 1286 512
10 B 135 7 1755 844
15 S 136 3 1203 16
10 B 137 0 1930 615
20 B 138 6 1270 82
6 C 114
1 B 140 4 1264 493
12 S 141 5 1333 36
18 B 142 4 1730 389
30 C 104
29 C 117
27 C 108
30 S 147 6 1238 633
21 S 148 0 1368 101
14 S 149 6 1606 167
13 B 150 9 1770 936
13 S 151 7 1785 402
28 S 152 2 1308 955
18 B 153 8 1279 836
14 B 154 5 1644 291
4 C 110
11 S 156 9 1423 483
21 C 115
16 B 158 8 1820 792
4 S 160 0 1687 244
9 B 162 0 1852 219
27 C 108
22 B 164 3 1376 534
1 B 166 8 1914 12
30 C 147
29 C 117
30 C 104
1 C 140
13 B 171 1 1050 259
22 S 172 8 1597 436
4 S 173 1 1560 273
7 C 125
6 S 176 0 1885 235
1 B 177 9 1543 37
21 B 178 4 1241 205
21 C 148
18 C 153
0 B 181 2 1270 120
27 B 182 6 1430 717
15 B 184 7 1976 761
9 B 185 1 1548 909
2 S 186 4 1880 264
29 C 117
22 C 164
17 S 189 5 1722 694
11 S 190 2 1719 436
20 C 127
12 S 192 3 1365 717
15 B 193 1 1611 547
25 C 123
29 C 117
9 S 196 5 1140 388
12 S 197 3 1019 717
25 S 198 4 1492 701
21 B 199 9 1436 485
18 C 153
5 S 201 8 1601 622
14 C 149
1 B 203 9 1966 116
16 C 134
10 S 205 4 1013 507
6 S 206 2 1843 415
16 C 158
13 S 209 4 1816 48
17 C 189
3 S 211 1 1698 741
25 B 212 0 1767 640
5 S 213 2 1628 159
16 B 214 2 1651 871
11 S 215 3 1849 529
30 S 216 1 1724 455
12 S 217 4 1081 805
25 B 218 3 1995 217
2 B 219 6 1791 98
27 B 220 4 1020 419
15 B 221 9 1317 988
14 C 154
1 C 177
25 B 224 9 1900 550
7 C 125
2 B 226 5 1333 768
21 S 227 3 1672 70
27 B 228 1 1711 537
30 S 229 5 1351 499
14 B 230 3 1689 10
16 C 105
14 B 232 1 1817 108
5 B 233 8 1618 46
8 B 234 1 1354 892
27 B 235 5 1234 311
12 S 236 2 1936 363
1 S 237 2 1560 941
23 B 238 7 1988 64
9 B 239 4 1214 220
9 B 240 2 1089 573
30 C 147
10 C 135
30 C 104
6 C 114
14 B 245 4 1002 248
10 C 205
4 C 173
28 C 152
30 S 249 8 1635 377
12 S 250 5 1144 584
31 S 251 8 1463 251
0 B 252 2 1734 597
0 C 252
24 B 254 0 1258 245
1 S 255 1 1360 127
1 S 256 0 1215 648
4 C 130
13 S 258 5 1498 941
8 S 259 1 1830 393
29 B 260 3 1021 822
1 S 261 9 1974 154
1 C 261
0 C 252
27 S 264 9 1311 914
14 C 154
19 S 266 2 1637 641
8 B 267 2 1047 34
27 B 268 1 1421 83
28 C 152
26 B 270 4 1408 540
3 B 271 2 1116 504
19 S 272 0 1052 82
31 C 251
4 B 274 8 1029 468
10 C 137
6 B 276 2 1902 28
15 C 221
11 C 190
29 B 279 0 1196 678
2 B 280 7 1384 142
18 B 281 2 1605 151
22 C 164
29 C 117
19 S 284 8 1074 58
6 S 285 5 1709 116
4 C 130
20 S 287 7 1079 715
16 S 288 0 1500 73
31 B 289 3 1046 270
14 C 154
11 S 291 4 1930 688
16 C 214
17 C 189
13 B 294 9 1564 952
29 B 295 2 1869 631
13 C 150
31 B 297 2 1393 484
3 B 298 4 1705 218
24 B 299 0 1227 986
4 C 110
5 C 201
24 S 302 5 1705 468
29 S 303 5 1916 887
5 S 304 3 1411 211
1 B 305 7 1562 105
23 S 306 8 1031 763
29 S 307 2 1128 931
7 C 125
12 B 309 3 1531 114
12 B 310 1 1085 762
8 S 311 2 1587 170
29 S 312 1 1916 253
26 B 313 9 1054 991
24 S 314 3 1968 466
9 C 240
10 C 137
29 C 260
8 B 318 4 1285 43
11 C 291
8 C 311
26 B 321 1 1110 769
22 B 322 2 1047 280
21 C 148
4 S 324 0 1406 856
23 S 325 0 1634 797
2 B 326 5 1864 417
29 C 279
25 B 328 9 1359 861
30 C 216
1 B 330 7 1860 197
0 B 331 9 1952 16
8 B 332 1 1452 492
26 S 333 8 1055 262
10 C 205
3 B 335 5 1224 316
0 C 252
21 S 337 2 1579 917
9 C 185
15 C 136
31 B 340 7 1568 748
31 C 297
3 S 342 0 1442 562
0 C 331
30 S 344 4 1822 912
4 C 160
6 C 114
30 B 347 5 1423 178
8 C 332
7 C 125
8 B 350 8 1670 512
15 S 351 1 1969 93
0 S 352 6 1433 146
16 C 134
2 S 354 6 1033 286
28 S 355 8 1556 963
28 S 356 5 1346 421
7 B 357 8 1435 744
7 S 358 5 1335 193
25 B 359 0 1379 439
3 B 360 1 1167 979
13 B 361 6 1209 197
1 B 362 0 1640 929
7 C 357
9 S 364 5 1417 522
21 S 365 1 1070 984
3 B 366 1 1227 873
11 C 156
13 C 258
17 B 369 7 1739 141
7 B 370 1 1125 545
8 S 371 5 1534 883
13 S 372 2 1936 179
10 B 373 0 1650 350
0 B 374 1 1551 904
5 S 375 4 1749 803
31 S 376 4 1597 624
18 C 142
16 C 158
7 B 379 6 1329 254
11 C 291
7 B 381 2 1201 57
21 B 382 3 1404 141
0 C 181
27 B 384 8 1434 938
1 B 385 5 1446 605
23 C 325
22 C 322
19 B 388 5 1407 93
8 C 318
28 C 152
27 S 391 2 1696 100
12 B 392 0 1046 330
1 C 255
4 B 394 7 1370 741
16 C 214
22 C 172
11 B 397 8 1757 768
31 B 398 2 1505 234
16 C 158
0 C 331
1 C 140
21 C 365
25 C 123
2 S 404 0 1687 736
25 S 405 5 1163 112
28 S 406 3 1025 836
20 C 120
31 S 408 4 1426 282
18 C 153
7 B 410 9 1128 614
17 S 411 4 1185 266
13 B 412 1 1113 758
4 S 413 7 1525 101
21 S 414 9 1078 879
11 S 415 0 1593 820
23 C 325
8 C 318
30 S 418 4 1921 649
18 C 153
23 S 420 9 1568 689
17 S 421 5 1696 921
27 B 422 7 1994 906
20 C 287
21 C 178
28 B 425 4 1908 945
25 B 426 7 1509 261
0 S 427 5 1597 85
29 S 428 7 1853 754
20 S 429 4 1735 879
31 B 430 0 1873 293
6 S 431 7 1252 141
17 B 432 1 1930 955
28 C 406
1 C 203
9 S 435 9 1609 226
22 C 111
8 S 437 5 1032 574
25 S 438 6 1873 378
31 C 430
20 B 440 0 1227 370
19 C 284
19 C 284
1 S 443 2 1167 407
26 B 444 0 1337 497
21 C 178
31 S 446 6 1047 513
1 B 447 8 1402 822
15 B 448 4 1400 265
8 S 449 4 1108 789
9 C 196
27 B 451 4 1532 583
28 B 452 4 1037 683
11 B 453 3 1913 448
19 C 131
27 B 455 9 1746 348
5 C 201
13 S 457 8 1964 865
18 C 281
0 S 459 9 1206 805
6 B 460 5 1303 338
3 S 461 2 1534 942
18 S 462 0 1411 624
21 B 463 4 1161 505
5 C 304
19 S 465 7 1732 518
29 B 466 8 1845 239
10 S 467 6 1313 717
12 S 468 2 1794 661
26 S 469 9 1074 702
28 C 425
16 C 105
11 S 472 7 1550 181
29 B 473 0 1269 655
2 B 474 5 1322 774
13 B 475 0 1437 779
14 C 245
3 B 477 2 1530 754
31 C 376
4 C 324
17 B 480 5 1645 191
23 C 306
26 S 482 4 1837 149
2 C 354
14 B 484 4 1683 499
29 C 428
12 S 486 8 1231 943
6 C 431
0 B 488 4 1975 720
29 S 489 7 1215 519
5 B 490 9 1381 258
3 B 491 3 1032 183
28 S 492 6 1720 338
6 B 493 8 1115 957
19 B 494 5 1099 228
29 C 307
26 S 496 1 1037 319
8 S 497 6 1584 580
29 S 498 2 1141 18
26 C 469
10 B 500 0 1182 508
26 B 501 7 1580 789
9 B 502 7 1351 981
18 S 503 0 1214 621
6 S 504 0 1680 610
14 C 232
5 C 201
13 B 507 0 1788 772
11 C 215
28 S 509 8 1005 306
12 C 250
12 C 310
31 C 408
30 S 513 6 1417 426
26 B 514 1 1805 692
21 C 337
23 B 516 6 1904 857
11 B 517 0 1050 769
2 C 226
30 C 344
18 C 462
20 S 521 6 1942 624
1 C 362
30 B 523 0 1171 133
6 S 524 6 1191 936
25 S 525 3 1568 837
14 S 526 7 1564 705
27 S 527 8 1602 524
20 B 528 1 1644 51
3 C 342
24 S 530 1 1350 665
31 C 297
19 C 388
18 S 533 6 1605 537
14 S 534 7 1522 929
27 C 235
12 C 236
7 B 537 7 1154 689
0 B 538 4 1946 497
6 S 539 9 1412 433
16 B 540 1 1733 267
9 C 240
28 B 542 0 1346 451
11 S 543 0 1968 654
24 B 544 8 1002 614
0 S 545 4 1849 235
28 B 546 9 1485 56
14 C 245
27 S 548 1 1081 534
10 S 549 4 1020 23
3 B 550 2 1101 156
16 S 551 6 1214 780
18 C 142
4 B 553 7 1794 84
11 S 554 7 1330 840
4 B 555 3 1592 841
14 S 556 2 1619 691
22 S 557 5 1292 429
29 B 558 8 1879 151
6 C 460
9 C 502
23 C 306
18 B 562 5 1901 457
10 S 563 7 1725 683
27 S 564 2 1046 12
23 B 565 7 1777 579
23 S 566 4 1860 459
11 B 567 7 1076 285
27 C 384
7 C 410
12 B 570 0 1439 140
31 B 571 6 1018 472
10 B 572 3 1246 515
15 C 221
8 B 574 4 1669 811
23 B 575 5 1101 790
14 S 576 1 1093 192
1 S 577 8 1653 916
7 S 578 2 1375 778
22 S 579 1 1355 530
20 C 440
29 C 295
18 B 582 4 1016 933
29 B 583 6 1638 118
30 B 584 9 1911 465
21 B 585 7 1960 384
27 S 586 6 1533 719
31 B 587 3 1860 661
5 C 304
24 S 589 5 1211 276
31 B 590 3 1708 100
2 B 591 9 1348 630
0 C 331
25 S 593 4 1725 797
2 B 594 9 1353 17
24 S 595 9 1326 750
3 S 596 3 1917 517
31 S 597 5 1024 984
16 B 598 6 1853 720
31 B 599 1 1999 126
2 C 280
27 B 601 0 1210 256
26 S 602 1 1856 607
19 C 284
23 S 604 2 1055 764
23 C 306
14 S 606 6 1686 691
18 C 562
17 C 432
23 B 609 8 1645 890
29 S 610 9 1317 114
15 S 611 9 1942 157
15 S 612 5 1100 546
14 S 613 3 1874 75
20 S 614 7 1105 580
2 B 615 1 1713 167
5 S 616 3 1074 486
23 C 306
